Workbook

Sheet Sheet1
A1: 코드 | B1: 품목 | C1: IP | D1: 품목명 | E1: 단가 | F1: 2609 | G1: 2608 | H1: 2607 | I1: 2606 | J1: 2605 | K1: 2604 | L1: 2603 | M1: 2602 | N1: 2601 | O1: 2512 | P1: 2511 | Q1: 2510 | R1: 2509 | S1: 2508 | T1: 2507 | U1: 2506 | V1: 2505 | W1: 2504 | X1: 2503 | Y1: 2502 | Z1: 2501
A2: =MID(B2,3,2) -> T2 | B2: EET224027 | C2: =_xlfn.XLOOKUP(B2,IP구분!A:A,IP구분!C:C) -> 퍼글러 | D2: 퍼글러 키링3_맥구 믹스 | E2: =IFERROR(_xlfn.XLOOKUP(B2,단가!A:A,단가!C:C),0) -> 2900 | F2: =IFERROR(_xlfn.XLOOKUP(B2,'[1]2609 재고'!$I$1:$I$65536,'[1]2609 재고'!$K$1:$K$65536),0) -> 1863 | G2: =IFERROR(_xlfn.XLOOKUP(B2,[2]Sheet1!$H$1:$H$65536,[2]Sheet1!$K$1:$K$65536),0) -> 2126 | H2: =IFERROR(_xlfn.XLOOKUP(B2,[3]Sheet1!$H$1:$H$65536,[3]Sheet1!$J$1:$J$65536),0) -> 2453 | I2: =IFERROR(_xlfn.XLOOKUP(B2,[4]Sheet1!$H$1:$H$65536,[4]Sheet1!$J$1:$J$65536),0) -> 2711 | J2: =IFERROR(_xlfn.XLOOKUP(B2,[5]Sheet1!$H$1:$H$65536,[5]Sheet1!$J$1:$J$65536),0) -> 3251 | K2: =IFERROR(_xlfn.XLOOKUP(B2,[6]Sheet1!$H$1:$H$65536,[6]Sheet1!$J$1:$J$65536),0) -> 3436 | L2: =IFERROR(_xlfn.XLOOKUP(B2,[7]Sheet1!$H$1:$H$65536,[7]Sheet1!$J$1:$J$65536),0) -> 928 | M2: =IFERROR(_xlfn.XLOOKUP(B2,[8]Sheet1!$H$1:$H$65536,[8]Sheet1!$J$1:$J$65536),0) -> 1110 | N2: =IFERROR(_xlfn.XLOOKUP(B2,[9]Sheet1!$H$1:$H$65536,[9]Sheet1!$J$1:$J$65536),0) -> 1278 | O2: =IFERROR(_xlfn.XLOOKUP(B2,[10]Sheet1!$H$1:$H$65536,[10]Sheet1!$J$1:$J$65536),0) -> 1846 | P2: =IFERROR(_xlfn.XLOOKUP(B2,[11]Sheet1!$H$1:$H$65536,[11]Sheet1!$J$1:$J$65536),0) -> 2728 | Q2: =IFERROR(_xlfn.XLOOKUP(B2,[12]Sheet1!$H$1:$H$65536,[12]Sheet1!$J$1:$J$65536),0) -> 4216 | R2: =IFERROR(_xlfn.XLOOKUP(B2,[13]Sheet1!$H$1:$H$65536,[13]Sheet1!$J$1:$J$65536),) -> 674 | S2: =IFERROR(_xlfn.XLOOKUP(B2,[14]Sheet1!$H$1:$H$65536,[14]Sheet1!$K$1:$K$65536),0) -> 390 | T2: =IFERROR(_xlfn.XLOOKUP(B2,[15]Sheet1!$H$1:$H$65536,[15]Sheet1!$J$1:$J$65536),0) -> 1343 | U2: =IFERROR(_xlfn.XLOOKUP(B2,[16]Sheet1!$H$1:$H$65536,[16]Sheet1!$J$1:$J$65536),0) -> 2695 | V2: =IFERROR(_xlfn.XLOOKUP(B2,[17]Sheet1!$H$1:$H$65536,[17]Sheet1!$J$1:$J$65536),0) -> 3865 | W2: =IFERROR(_xlfn.XLOOKUP(B2,[18]Sheet1!$H$1:$H$65536,[18]Sheet1!$J$1:$J$65536),0) -> 1616 | X2: =IFERROR(_xlfn.XLOOKUP(B2,[19]Sheet1!$H$1:$H$65536,[19]Sheet1!$J$1:$J$65536),0) -> 2358 | Y2: =IFERROR(_xlfn.XLOOKUP(B2,[20]Sheet1!$H$1:$H$65536,[20]Sheet1!$J$1:$J$65536),0) -> 3039 | Z2: =IFERROR(_xlfn.XLOOKUP(B2,[21]Sheet1!$H$1:$H$65536,[21]Sheet1!$J$1:$J$65536),0) -> 3578
A3: =MID(B3,3,2) -> T2 | B3: EET224054 | C3: =_xlfn.XLOOKUP(B3,IP구분!A:A,IP구분!C:C) -> 퍼글러 | D3: 퍼글러 글로우-먼츠먼츠 | E3: =IFERROR(_xlfn.XLOOKUP(B3,단가!A:A,단가!C:C),0) -> 5566 | F3: =IFERROR(_xlfn.XLOOKUP(B3,'[1]2609 재고'!$I$1:$I$65536,'[1]2609 재고'!$K$1:$K$65536),0) -> 1 | G3: =IFERROR(_xlfn.XLOOKUP(B3,[2]Sheet1!$H$1:$H$65536,[2]Sheet1!$K$1:$K$65536),0) -> 6 | H3: =IFERROR(_xlfn.XLOOKUP(B3,[3]Sheet1!$H$1:$H$65536,[3]Sheet1!$J$1:$J$65536),0) -> 6 | I3: =IFERROR(_xlfn.XLOOKUP(B3,[4]Sheet1!$H$1:$H$65536,[4]Sheet1!$J$1:$J$65536),0) -> 6 | J3: =IFERROR(_xlfn.XLOOKUP(B3,[5]Sheet1!$H$1:$H$65536,[5]Sheet1!$J$1:$J$65536),0) -> 9 | K3: =IFERROR(_xlfn.XLOOKUP(B3,[6]Sheet1!$H$1:$H$65536,[6]Sheet1!$J$1:$J$65536),0) -> 6 | L3: =IFERROR(_xlfn.XLOOKUP(B3,[7]Sheet1!$H$1:$H$65536,[7]Sheet1!$J$1:$J$65536),0) -> 9 | M3: =IFERROR(_xlfn.XLOOKUP(B3,[8]Sheet1!$H$1:$H$65536,[8]Sheet1!$J$1:$J$65536),0) -> 42 | N3: =IFERROR(_xlfn.XLOOKUP(B3,[9]Sheet1!$H$1:$H$65536,[9]Sheet1!$J$1:$J$65536),0) -> 42 | O3: =IFERROR(_xlfn.XLOOKUP(B3,[10]Sheet1!$H$1:$H$65536,[10]Sheet1!$J$1:$J$65536),0) -> 42 | P3: =IFERROR(_xlfn.XLOOKUP(B3,[11]Sheet1!$H$1:$H$65536,[11]Sheet1!$J$1:$J$65536),0) -> 126 | Q3: =IFERROR(_xlfn.XLOOKUP(B3,[12]Sheet1!$H$1:$H$65536,[12]Sheet1!$J$1:$J$65536),0) -> 195 | R3: =IFERROR(_xlfn.XLOOKUP(B3,[13]Sheet1!$H$1:$H$65536,[13]Sheet1!$J$1:$J$65536),) -> 224 | S3: =IFERROR(_xlfn.XLOOKUP(B3,[14]Sheet1!$H$1:$H$65536,[14]Sheet1!$K$1:$K$65536),0) -> 257 | T3: =IFERROR(_xlfn.XLOOKUP(B3,[15]Sheet1!$H$1:$H$65536,[15]Sheet1!$J$1:$J$65536),0) -> 296 | U3: =IFERROR(_xlfn.XLOOKUP(B3,[16]Sheet1!$H$1:$H$65536,[16]Sheet1!$J$1:$J$65536),0) -> 348 | V3: =IFERROR(_xlfn.XLOOKUP(B3,[17]Sheet1!$H$1:$H$65536,[17]Sheet1!$J$1:$J$65536),0) -> 373 | W3: =IFERROR(_xlfn.XLOOKUP(B3,[18]Sheet1!$H$1:$H$65536,[18]Sheet1!$J$1:$J$65536),0) -> 393 | X3: =IFERROR(_xlfn.XLOOKUP(B3,[19]Sheet1!$H$1:$H$65536,[19]Sheet1!$J$1:$J$65536),0) -> 407 | Y3: =IFERROR(_xlfn.XLOOKUP(B3,[20]Sheet1!$H$1:$H$65536,[20]Sheet1!$J$1:$J$65536),0) -> 427 | Z3: =IFERROR(_xlfn.XLOOKUP(B3,[21]Sheet1!$H$1:$H$65536,[21]Sheet1!$J$1:$J$65536),0) -> 442
A4: =MID(B4,3,2) -> M2 | B4: EEM224014 | C4: =_xlfn.XLOOKUP(B4,IP구분!A:A,IP구분!C:C) -> 퍼글러 | D4: 퍼글러 사계절 파자마 (핑크) XL | E4: =IFERROR(_xlfn.XLOOKUP(B4,단가!A:A,단가!C:C),0) -> 10500 | F4: =IFERROR(_xlfn.XLOOKUP(B4,'[1]2609 재고'!$I$1:$I$65536,'[1]2609 재고'!$K$1:$K$65536),0) -> 467 | G4: =IFERROR(_xlfn.XLOOKUP(B4,[2]Sheet1!$H$1:$H$65536,[2]Sheet1!$K$1:$K$65536),0) -> 473 | H4: =IFERROR(_xlfn.XLOOKUP(B4,[3]Sheet1!$H$1:$H$65536,[3]Sheet1!$J$1:$J$65536),0) -> 473 | I4: =IFERROR(_xlfn.XLOOKUP(B4,[4]Sheet1!$H$1:$H$65536,[4]Sheet1!$J$1:$J$65536),0) -> 476 | J4: =IFERROR(_xlfn.XLOOKUP(B4,[5]Sheet1!$H$1:$H$65536,[5]Sheet1!$J$1:$J$65536),0) -> 480 | K4: =IFERROR(_xlfn.XLOOKUP(B4,[6]Sheet1!$H$1:$H$65536,[6]Sheet1!$J$1:$J$65536),0) -> 478 | L4: =IFERROR(_xlfn.XLOOKUP(B4,[7]Sheet1!$H$1:$H$65536,[7]Sheet1!$J$1:$J$65536),0) -> 483 | M4: =IFERROR(_xlfn.XLOOKUP(B4,[8]Sheet1!$H$1:$H$65536,[8]Sheet1!$J$1:$J$65536),0) -> 480 | N4: =IFERROR(_xlfn.XLOOKUP(B4,[9]Sheet1!$H$1:$H$65536,[9]Sheet1!$J$1:$J$65536),0) -> 482 | O4: =IFERROR(_xlfn.XLOOKUP(B4,[10]Sheet1!$H$1:$H$65536,[10]Sheet1!$J$1:$J$65536),0) -> 483 | P4: =IFERROR(_xlfn.XLOOKUP(B4,[11]Sheet1!$H$1:$H$65536,[11]Sheet1!$J$1:$J$65536),0) -> 487 | Q4: =IFERROR(_xlfn.XLOOKUP(B4,[12]Sheet1!$H$1:$H$65536,[12]Sheet1!$J$1:$J$65536),0) -> 494 | R4: =IFERROR(_xlfn.XLOOKUP(B4,[13]Sheet1!$H$1:$H$65536,[13]Sheet1!$J$1:$J$65536),) -> 496 | S4: =IFERROR(_xlfn.XLOOKUP(B4,[14]Sheet1!$H$1:$H$65536,[14]Sheet1!$K$1:$K$65536),0) -> 510 | T4: =IFERROR(_xlfn.XLOOKUP(B4,[15]Sheet1!$H$1:$H$65536,[15]Sheet1!$J$1:$J$65536),0) -> 511 | U4: =IFERROR(_xlfn.XLOOKUP(B4,[16]Sheet1!$H$1:$H$65536,[16]Sheet1!$J$1:$J$65536),0) -> 513 | V4: =IFERROR(_xlfn.XLOOKUP(B4,[17]Sheet1!$H$1:$H$65536,[17]Sheet1!$J$1:$J$65536),0) -> 528 | W4: =IFERROR(_xlfn.XLOOKUP(B4,[18]Sheet1!$H$1:$H$65536,[18]Sheet1!$J$1:$J$65536),0) -> 533 | X4: =IFERROR(_xlfn.XLOOKUP(B4,[19]Sheet1!$H$1:$H$65536,[19]Sheet1!$J$1:$J$65536),0) -> 536 | Y4: =IFERROR(_xlfn.XLOOKUP(B4,[20]Sheet1!$H$1:$H$65536,[20]Sheet1!$J$1:$J$65536),0) -> 543 | Z4: =IFERROR(_xlfn.XLOOKUP(B4,[21]Sheet1!$H$1:$H$65536,[21]Sheet1!$J$1:$J$65536),0) -> 545
A5: =MID(B5,3,2) -> T2 | B5: EET224028 | C5: =_xlfn.XLOOKUP(B5,IP구분!A:A,IP구분!C:C) -> 퍼글러 | D5: 퍼글러 키링3_몬스터 믹스 | E5: =IFERROR(_xlfn.XLOOKUP(B5,단가!A:A,단가!C:C),0) -> 2765 | F5: =IFERROR(_xlfn.XLOOKUP(B5,'[1]2609 재고'!$I$1:$I$65536,'[1]2609 재고'!$K$1:$K$65536),0) -> 243 | G5: =IFERROR(_xlfn.XLOOKUP(B5,[2]Sheet1!$H$1:$H$65536,[2]Sheet1!$K$1:$K$65536),0) -> 298 | H5: =IFERROR(_xlfn.XLOOKUP(B5,[3]Sheet1!$H$1:$H$65536,[3]Sheet1!$J$1:$J$65536),0) -> 350 | I5: =IFERROR(_xlfn.XLOOKUP(B5,[4]Sheet1!$H$1:$H$65536,[4]Sheet1!$J$1:$J$65536),0) -> 412 | J5: =IFERROR(_xlfn.XLOOKUP(B5,[5]Sheet1!$H$1:$H$65536,[5]Sheet1!$J$1:$J$65536),0) -> 500 | K5: =IFERROR(_xlfn.XLOOKUP(B5,[6]Sheet1!$H$1:$H$65536,[6]Sheet1!$J$1:$J$65536),0) -> 546 | L5: =IFERROR(_xlfn.XLOOKUP(B5,[7]Sheet1!$H$1:$H$65536,[7]Sheet1!$J$1:$J$65536),0) -> 623 | M5: =IFERROR(_xlfn.XLOOKUP(B5,[8]Sheet1!$H$1:$H$65536,[8]Sheet1!$J$1:$J$65536),0) -> 718 | N5: =IFERROR(_xlfn.XLOOKUP(B5,[9]Sheet1!$H$1:$H$65536,[9]Sheet1!$J$1:$J$65536),0) -> 769 | O5: =IFERROR(_xlfn.XLOOKUP(B5,[10]Sheet1!$H$1:$H$65536,[10]Sheet1!$J$1:$J$65536),0) -> 878 | P5: =IFERROR(_xlfn.XLOOKUP(B5,[11]Sheet1!$H$1:$H$65536,[11]Sheet1!$J$1:$J$65536),0) -> 987 | Q5: =IFERROR(_xlfn.XLOOKUP(B5,[12]Sheet1!$H$1:$H$65536,[12]Sheet1!$J$1:$J$65536),0) -> 1196 | R5: =IFERROR(_xlfn.XLOOKUP(B5,[13]Sheet1!$H$1:$H$65536,[13]Sheet1!$J$1:$J$65536),) -> 1472 | S5: =IFERROR(_xlfn.XLOOKUP(B5,[14]Sheet1!$H$1:$H$65536,[14]Sheet1!$K$1:$K$65536),0) -> 2248 | T5: =IFERROR(_xlfn.XLOOKUP(B5,[15]Sheet1!$H$1:$H$65536,[15]Sheet1!$J$1:$J$65536),0) -> 2934 | U5: =IFERROR(_xlfn.XLOOKUP(B5,[16]Sheet1!$H$1:$H$65536,[16]Sheet1!$J$1:$J$65536),0) -> 3555 | V5: =IFERROR(_xlfn.XLOOKUP(B5,[17]Sheet1!$H$1:$H$65536,[17]Sheet1!$J$1:$J$65536),0) -> 3755 | W5: =IFERROR(_xlfn.XLOOKUP(B5,[18]Sheet1!$H$1:$H$65536,[18]Sheet1!$J$1:$J$65536),0) -> 1113 | X5: =IFERROR(_xlfn.XLOOKUP(B5,[19]Sheet1!$H$1:$H$65536,[19]Sheet1!$J$1:$J$65536),0) -> 1264 | Y5: =IFERROR(_xlfn.XLOOKUP(B5,[20]Sheet1!$H$1:$H$65536,[20]Sheet1!$J$1:$J$65536),0) -> 1584 | Z5: =IFERROR(_xlfn.XLOOKUP(B5,[21]Sheet1!$H$1:$H$65536,[21]Sheet1!$J$1:$J$65536),0) -> 1817
A6: =MID(B6,3,2) -> T2 | B6: EET225004 | C6: =_xlfn.XLOOKUP(B6,IP구분!A:A,IP구분!C:C) -> 퍼글러 | D6: 퍼글러 반지의 제왕_프로도 | E6: =IFERROR(_xlfn.XLOOKUP(B6,단가!A:A,단가!C:C),0) -> 8601 | F6: =IFERROR(_xlfn.XLOOKUP(B6,'[1]2609 재고'!$I$1:$I$65536,'[1]2609 재고'!$K$1:$K$65536),0) -> 386 | G6: =IFERROR(_xlfn.XLOOKUP(B6,[2]Sheet1!$H$1:$H$65536,[2]Sheet1!$K$1:$K$65536),0) -> 419 | H6: =IFERROR(_xlfn.XLOOKUP(B6,[3]Sheet1!$H$1:$H$65536,[3]Sheet1!$J$1:$J$65536),0) -> 436 | I6: =IFERROR(_xlfn.XLOOKUP(B6,[4]Sheet1!$H$1:$H$65536,[4]Sheet1!$J$1:$J$65536),0) -> 443 | J6: =IFERROR(_xlfn.XLOOKUP(B6,[5]Sheet1!$H$1:$H$65536,[5]Sheet1!$J$1:$J$65536),0) -> 450 | K6: =IFERROR(_xlfn.XLOOKUP(B6,[6]Sheet1!$H$1:$H$65536,[6]Sheet1!$J$1:$J$65536),0) -> 452 | L6: =IFERROR(_xlfn.XLOOKUP(B6,[7]Sheet1!$H$1:$H$65536,[7]Sheet1!$J$1:$J$65536),0) -> 474 | M6: =IFERROR(_xlfn.XLOOKUP(B6,[8]Sheet1!$H$1:$H$65536,[8]Sheet1!$J$1:$J$65536),0) -> 476 | N6: =IFERROR(_xlfn.XLOOKUP(B6,[9]Sheet1!$H$1:$H$65536,[9]Sheet1!$J$1:$J$65536),0) -> 496 | O6: =IFERROR(_xlfn.XLOOKUP(B6,[10]Sheet1!$H$1:$H$65536,[10]Sheet1!$J$1:$J$65536),0) -> 503 | P6: =IFERROR(_xlfn.XLOOKUP(B6,[11]Sheet1!$H$1:$H$65536,[11]Sheet1!$J$1:$J$65536),0) -> 545 | Q6: =IFERROR(_xlfn.XLOOKUP(B6,[12]Sheet1!$H$1:$H$65536,[12]Sheet1!$J$1:$J$65536),0) -> 886 | R6: =IFERROR(_xlfn.XLOOKUP(B6,[13]Sheet1!$H$1:$H$65536,[13]Sheet1!$J$1:$J$65536),) -> 915 | S6: =IFERROR(_xlfn.XLOOKUP(B6,[14]Sheet1!$H$1:$H$65536,[14]Sheet1!$K$1:$K$65536),0) -> 980 | T6: =IFERROR(_xlfn.XLOOKUP(B6,[15]Sheet1!$H$1:$H$65536,[15]Sheet1!$J$1:$J$65536),0) -> 1121 | U6: =IFERROR(_xlfn.XLOOKUP(B6,[16]Sheet1!$H$1:$H$65536,[16]Sheet1!$J$1:$J$65536),0) -> 1161 | V6: =IFERROR(_xlfn.XLOOKUP(B6,[17]Sheet1!$H$1:$H$65536,[17]Sheet1!$J$1:$J$65536),0) -> 1197 | W6: =IFERROR(_xlfn.XLOOKUP(B6,[18]Sheet1!$H$1:$H$65536,[18]Sheet1!$J$1:$J$65536),0) -> 0 | X6: =IFERROR(_xlfn.XLOOKUP(B6,[19]Sheet1!$H$1:$H$65536,[19]Sheet1!$J$1:$J$65536),0) -> 0 | Y6: =IFERROR(_xlfn.XLOOKUP(B6,[20]Sheet1!$H$1:$H$65536,[20]Sheet1!$J$1:$J$65536),0) -> 0 | Z6: =IFERROR(_xlfn.XLOOKUP(B6,[21]Sheet1!$H$1:$H$65536,[21]Sheet1!$J$1:$J$65536),0) -> 0
A7: =MID(B7,3,2) -> T2 | B7: EET225013 | C7: =_xlfn.XLOOKUP(B7,IP구분!A:A,IP구분!C:C) -> 퍼글러 | D7: 퍼글러 키링5_롱롱이어 핑크 | E7: =IFERROR(_xlfn.XLOOKUP(B7,단가!A:A,단가!C:C),0) -> 3004 | F7: =IFERROR(_xlfn.XLOOKUP(B7,'[1]2609 재고'!$I$1:$I$65536,'[1]2609 재고'!$K$1:$K$65536),0) -> 476 | G7: =IFERROR(_xlfn.XLOOKUP(B7,[2]Sheet1!$H$1:$H$65536,[2]Sheet1!$K$1:$K$65536),0) -> 603 | H7: =IFERROR(_xlfn.XLOOKUP(B7,[3]Sheet1!$H$1:$H$65536,[3]Sheet1!$J$1:$J$65536),0) -> 840 | I7: =IFERROR(_xlfn.XLOOKUP(B7,[4]Sheet1!$H$1:$H$65536,[4]Sheet1!$J$1:$J$65536),0) -> 947 | J7: =IFERROR(_xlfn.XLOOKUP(B7,[5]Sheet1!$H$1:$H$65536,[5]Sheet1!$J$1:$J$65536),0) -> 1194 | K7: =IFERROR(_xlfn.XLOOKUP(B7,[6]Sheet1!$H$1:$H$65536,[6]Sheet1!$J$1:$J$65536),0) -> 1366 | L7: =IFERROR(_xlfn.XLOOKUP(B7,[7]Sheet1!$H$1:$H$65536,[7]Sheet1!$J$1:$J$65536),0) -> 1632 | M7: =IFERROR(_xlfn.XLOOKUP(B7,[8]Sheet1!$H$1:$H$65536,[8]Sheet1!$J$1:$J$65536),0) -> 1799 | N7: =IFERROR(_xlfn.XLOOKUP(B7,[9]Sheet1!$H$1:$H$65536,[9]Sheet1!$J$1:$J$65536),0) -> 2092 | O7: =IFERROR(_xlfn.XLOOKUP(B7,[10]Sheet1!$H$1:$H$65536,[10]Sheet1!$J$1:$J$65536),0) -> 2434 | P7: =IFERROR(_xlfn.XLOOKUP(B7,[11]Sheet1!$H$1:$H$65536,[11]Sheet1!$J$1:$J$65536),0) -> 3207 | Q7: =IFERROR(_xlfn.XLOOKUP(B7,[12]Sheet1!$H$1:$H$65536,[12]Sheet1!$J$1:$J$65536),0) -> 1062 | R7: =IFERROR(_xlfn.XLOOKUP(B7,[13]Sheet1!$H$1:$H$65536,[13]Sheet1!$J$1:$J$65536),) -> 1298 | S7: =IFERROR(_xlfn.XLOOKUP(B7,[14]Sheet1!$H$1:$H$65536,[14]Sheet1!$K$1:$K$65536),0) -> 1447 | T7: =IFERROR(_xlfn.XLOOKUP(B7,[15]Sheet1!$H$1:$H$65536,[15]Sheet1!$J$1:$J$65536),0) -> 1629 | U7: =IFERROR(_xlfn.XLOOKUP(B7,[16]Sheet1!$H$1:$H$65536,[16]Sheet1!$J$1:$J$65536),0) -> 2548 | V7: =IFERROR(_xlfn.XLOOKUP(B7,[17]Sheet1!$H$1:$H$65536,[17]Sheet1!$J$1:$J$65536),0) -> 2968 | W7: =IFERROR(_xlfn.XLOOKUP(B7,[18]Sheet1!$H$1:$H$65536,[18]Sheet1!$J$1:$J$65536),0) -> 0 | X7: =IFERROR(_xlfn.XLOOKUP(B7,[19]Sheet1!$H$1:$H$65536,[19]Sheet1!$J$1:$J$65536),0) -> 0 | Y7: =IFERROR(_xlfn.XLOOKUP(B7,[20]Sheet1!$H$1:$H$65536,[20]Sheet1!$J$1:$J$65536),0) -> 0 | Z7: =IFERROR(_xlfn.XLOOKUP(B7,[21]Sheet1!$H$1:$H$65536,[21]Sheet1!$J$1:$J$65536),0) -> 0
A8: =MID(B8,3,2) -> T2 | B8: EET225040 | C8: =_xlfn.XLOOKUP(B8,IP구분!A:A,IP구분!C:C) -> 퍼글러 | D8: 라스칼_우가부가 핑크 롱 파일 | E8: =IFERROR(_xlfn.XLOOKUP(B8,단가!A:A,단가!C:C),0) -> 7447 | F8: =IFERROR(_xlfn.XLOOKUP(B8,'[1]2609 재고'!$I$1:$I$65536,'[1]2609 재고'!$K$1:$K$65536),0) -> 929 | G8: =IFERROR(_xlfn.XLOOKUP(B8,[2]Sheet1!$H$1:$H$65536,[2]Sheet1!$K$1:$K$65536),0) -> 1091 | H8: =IFERROR(_xlfn.XLOOKUP(B8,[3]Sheet1!$H$1:$H$65536,[3]Sheet1!$J$1:$J$65536),0) -> 1126 | I8: =IFERROR(_xlfn.XLOOKUP(B8,[4]Sheet1!$H$1:$H$65536,[4]Sheet1!$J$1:$J$65536),0) -> 1140 | J8: =IFERROR(_xlfn.XLOOKUP(B8,[5]Sheet1!$H$1:$H$65536,[5]Sheet1!$J$1:$J$65536),0) -> 1149 | K8: =IFERROR(_xlfn.XLOOKUP(B8,[6]Sheet1!$H$1:$H$65536,[6]Sheet1!$J$1:$J$65536),0) -> 1157 | L8: =IFERROR(_xlfn.XLOOKUP(B8,[7]Sheet1!$H$1:$H$65536,[7]Sheet1!$J$1:$J$65536),0) -> 1194 | M8: =IFERROR(_xlfn.XLOOKUP(B8,[8]Sheet1!$H$1:$H$65536,[8]Sheet1!$J$1:$J$65536),0) -> 1204 | N8: =IFERROR(_xlfn.XLOOKUP(B8,[9]Sheet1!$H$1:$H$65536,[9]Sheet1!$J$1:$J$65536),0) -> 1588 | O8: =IFERROR(_xlfn.XLOOKUP(B8,[10]Sheet1!$H$1:$H$65536,[10]Sheet1!$J$1:$J$65536),0) -> 399 | P8: =IFERROR(_xlfn.XLOOKUP(B8,[11]Sheet1!$H$1:$H$65536,[11]Sheet1!$J$1:$J$65536),0) -> 485 | Q8: =IFERROR(_xlfn.XLOOKUP(B8,[12]Sheet1!$H$1:$H$65536,[12]Sheet1!$J$1:$J$65536),0) -> 569 | R8: =IFERROR(_xlfn.XLOOKUP(B8,[13]Sheet1!$H$1:$H$65536,[13]Sheet1!$J$1:$J$65536),) -> 647 | S8: =IFERROR(_xlfn.XLOOKUP(B8,[14]Sheet1!$H$1:$H$65536,[14]Sheet1!$K$1:$K$65536),0) -> 0 | T8: =IFERROR(_xlfn.XLOOKUP(B8,[15]Sheet1!$H$1:$H$65536,[15]Sheet1!$J$1:$J$65536),0) -> 0 | U8: =IFERROR(_xlfn.XLOOKUP(B8,[16]Sheet1!$H$1:$H$65536,[16]Sheet1!$J$1:$J$65536),0) -> 0 | V8: =IFERROR(_xlfn.XLOOKUP(B8,[17]Sheet1!$H$1:$H$65536,[17]Sheet1!$J$1:$J$65536),0) -> 0 | W8: =IFERROR(_xlfn.XLOOKUP(B8,[18]Sheet1!$H$1:$H$65536,[18]Sheet1!$J$1:$J$65536),0) -> 0 | X8: =IFERROR(_xlfn.XLOOKUP(B8,[19]Sheet1!$H$1:$H$65536,[19]Sheet1!$J$1:$J$65536),0) -> 0 | Y8: =IFERROR(_xlfn.XLOOKUP(B8,[20]Sheet1!$H$1:$H$65536,[20]Sheet1!$J$1:$J$65536),0) -> 0 | Z8: =IFERROR(_xlfn.XLOOKUP(B8,[21]Sheet1!$H$1:$H$65536,[21]Sheet1!$J$1:$J$65536),0) -> 0
A9: =MID(B9,3,2) -> T2 | B9: EET225041 | C9: =_xlfn.XLOOKUP(B9,IP구분!A:A,IP구분!C:C) -> 퍼글러 | D9: 라스칼_스퀴지 브라운 롱 파일 | E9: =IFERROR(_xlfn.XLOOKUP(B9,단가!A:A,단가!C:C),0) -> 7445 | F9: =IFERROR(_xlfn.XLOOKUP(B9,'[1]2609 재고'!$I$1:$I$65536,'[1]2609 재고'!$K$1:$K$65536),0) -> 956 | G9: =IFERROR(_xlfn.XLOOKUP(B9,[2]Sheet1!$H$1:$H$65536,[2]Sheet1!$K$1:$K$65536),0) -> 1138 | H9: =IFERROR(_xlfn.XLOOKUP(B9,[3]Sheet1!$H$1:$H$65536,[3]Sheet1!$J$1:$J$65536),0) -> 1175 | I9: =IFERROR(_xlfn.XLOOKUP(B9,[4]Sheet1!$H$1:$H$65536,[4]Sheet1!$J$1:$J$65536),0) -> 1191 | J9: =IFERROR(_xlfn.XLOOKUP(B9,[5]Sheet1!$H$1:$H$65536,[5]Sheet1!$J$1:$J$65536),0) -> 1213 | K9: =IFERROR(_xlfn.XLOOKUP(B9,[6]Sheet1!$H$1:$H$65536,[6]Sheet1!$J$1:$J$65536),0) -> 1218 | L9: =IFERROR(_xlfn.XLOOKUP(B9,[7]Sheet1!$H$1:$H$65536,[7]Sheet1!$J$1:$J$65536),0) -> 1250 | M9: =IFERROR(_xlfn.XLOOKUP(B9,[8]Sheet1!$H$1:$H$65536,[8]Sheet1!$J$1:$J$65536),0) -> 1273 | N9: =IFERROR(_xlfn.XLOOKUP(B9,[9]Sheet1!$H$1:$H$65536,[9]Sheet1!$J$1:$J$65536),0) -> 1654 | O9: =IFERROR(_xlfn.XLOOKUP(B9,[10]Sheet1!$H$1:$H$65536,[10]Sheet1!$J$1:$J$65536),0) -> 447 | P9: =IFERROR(_xlfn.XLOOKUP(B9,[11]Sheet1!$H$1:$H$65536,[11]Sheet1!$J$1:$J$65536),0) -> 528 | Q9: =IFERROR(_xlfn.XLOOKUP(B9,[12]Sheet1!$H$1:$H$65536,[12]Sheet1!$J$1:$J$65536),0) -> 608 | R9: =IFERROR(_xlfn.XLOOKUP(B9,[13]Sheet1!$H$1:$H$65536,[13]Sheet1!$J$1:$J$65536),) -> 648 | S9: =IFERROR(_xlfn.XLOOKUP(B9,[14]Sheet1!$H$1:$H$65536,[14]Sheet1!$K$1:$K$65536),0) -> 0 | T9: =IFERROR(_xlfn.XLOOKUP(B9,[15]Sheet1!$H$1:$H$65536,[15]Sheet1!$J$1:$J$65536),0) -> 0 | U9: =IFERROR(_xlfn.XLOOKUP(B9,[16]Sheet1!$H$1:$H$65536,[16]Sheet1!$J$1:$J$65536),0) -> 0 | V9: =IFERROR(_xlfn.XLOOKUP(B9,[17]Sheet1!$H$1:$H$65536,[17]Sheet1!$J$1:$J$65536),0) -> 0 | W9: =IFERROR(_xlfn.XLOOKUP(B9,[18]Sheet1!$H$1:$H$65536,[18]Sheet1!$J$1:$J$65536),0) -> 0 | X9: =IFERROR(_xlfn.XLOOKUP(B9,[19]Sheet1!$H$1:$H$65536,[19]Sheet1!$J$1:$J$65536),0) -> 0 | Y9: =IFERROR(_xlfn.XLOOKUP(B9,[20]Sheet1!$H$1:$H$65536,[20]Sheet1!$J$1:$J$65536),0) -> 0 | Z9: =IFERROR(_xlfn.XLOOKUP(B9,[21]Sheet1!$H$1:$H$65536,[21]Sheet1!$J$1:$J$65536),0) -> 0
A10: =MID(B10,3,2) -> T2 | B10: EET225059 | C10: =_xlfn.XLOOKUP(B10,IP구분!A:A,IP구분!C:C) -> 퍼글러 | D10: 파워퍼프걸스_버터컵 | E10: =IFERROR(_xlfn.XLOOKUP(B10,단가!A:A,단가!C:C),0) -> 8303 | F10: =IFERROR(_xlfn.XLOOKUP(B10,'[1]2609 재고'!$I$1:$I$65536,'[1]2609 재고'!$K$1:$K$65536),0) -> 1684 | G10: =IFERROR(_xlfn.XLOOKUP(B10,[2]Sheet1!$H$1:$H$65536,[2]Sheet1!$K$1:$K$65536),0) -> 1704 | H10: =IFERROR(_xlfn.XLOOKUP(B10,[3]Sheet1!$H$1:$H$65536,[3]Sheet1!$J$1:$J$65536),0) -> 1726 | I10: =IFERROR(_xlfn.XLOOKUP(B10,[4]Sheet1!$H$1:$H$65536,[4]Sheet1!$J$1:$J$65536),0) -> 1734 | J10: =IFERROR(_xlfn.XLOOKUP(B10,[5]Sheet1!$H$1:$H$65536,[5]Sheet1!$J$1:$J$65536),0) -> 1764 | K10: =IFERROR(_xlfn.XLOOKUP(B10,[6]Sheet1!$H$1:$H$65536,[6]Sheet1!$J$1:$J$65536),0) -> 1767 | L10: =IFERROR(_xlfn.XLOOKUP(B10,[7]Sheet1!$H$1:$H$65536,[7]Sheet1!$J$1:$J$65536),0) -> 1787 | M10: =IFERROR(_xlfn.XLOOKUP(B10,[8]Sheet1!$H$1:$H$65536,[8]Sheet1!$J$1:$J$65536),0) -> 1817 | N10: =IFERROR(_xlfn.XLOOKUP(B10,[9]Sheet1!$H$1:$H$65536,[9]Sheet1!$J$1:$J$65536),0) -> 2227 | O10: =IFERROR(_xlfn.XLOOKUP(B10,[10]Sheet1!$H$1:$H$65536,[10]Sheet1!$J$1:$J$65536),0) -> 579 | P10: =IFERROR(_xlfn.XLOOKUP(B10,[11]Sheet1!$H$1:$H$65536,[11]Sheet1!$J$1:$J$65536),0) -> 0 | Q10: =IFERROR(_xlfn.XLOOKUP(B10,[12]Sheet1!$H$1:$H$65536,[12]Sheet1!$J$1:$J$65536),0) -> 0 | R10: =IFERROR(_xlfn.XLOOKUP(B10,[13]Sheet1!$H$1:$H$65536,[13]Sheet1!$J$1:$J$65536),) -> 0 | S10: =IFERROR(_xlfn.XLOOKUP(B10,[14]Sheet1!$H$1:$H$65536,[14]Sheet1!$K$1:$K$65536),0) -> 0 | T10: =IFERROR(_xlfn.XLOOKUP(B10,[15]Sheet1!$H$1:$H$65536,[15]Sheet1!$J$1:$J$65536),0) -> 0 | U10: =IFERROR(_xlfn.XLOOKUP(B10,[16]Sheet1!$H$1:$H$65536,[16]Sheet1!$J$1:$J$65536),0) -> 0 | V10: =IFERROR(_xlfn.XLOOKUP(B10,[17]Sheet1!$H$1:$H$65536,[17]Sheet1!$J$1:$J$65536),0) -> 0 | W10: =IFERROR(_xlfn.XLOOKUP(B10,[18]Sheet1!$H$1:$H$65536,[18]Sheet1!$J$1:$J$65536),0) -> 0 | X10: =IFERROR(_xlfn.XLOOKUP(B10,[19]Sheet1!$H$1:$H$65536,[19]Sheet1!$J$1:$J$65536),0) -> 0 | Y10: =IFERROR(_xlfn.XLOOKUP(B10,[20]Sheet1!$H$1:$H$65536,[20]Sheet1!$J$1:$J$65536),0) -> 0 | Z10: =IFERROR(_xlfn.XLOOKUP(B10,[21]Sheet1!$H$1:$H$65536,[21]Sheet1!$J$1:$J$65536),0) -> 0
A11: =MID(B11,3,2) -> T2 | B11: EET225063 | C11: =_xlfn.XLOOKUP(B11,IP구분!A:A,IP구분!C:C) -> 퍼글러 | D11: 퍼글러 키링6_올드 투스 | E11: =IFERROR(_xlfn.XLOOKUP(B11,단가!A:A,단가!C:C),0) -> 3123 | F11: =IFERROR(_xlfn.XLOOKUP(B11,'[1]2609 재고'!$I$1:$I$65536,'[1]2609 재고'!$K$1:$K$65536),0) -> 10525 | G11: =IFERROR(_xlfn.XLOOKUP(B11,[2]Sheet1!$H$1:$H$65536,[2]Sheet1!$K$1:$K$65536),0) -> 10796 | H11: =IFERROR(_xlfn.XLOOKUP(B11,[3]Sheet1!$H$1:$H$65536,[3]Sheet1!$J$1:$J$65536),0) -> 11229 | I11: =IFERROR(_xlfn.XLOOKUP(B11,[4]Sheet1!$H$1:$H$65536,[4]Sheet1!$J$1:$J$65536),0) -> 11480 | J11: =IFERROR(_xlfn.XLOOKUP(B11,[5]Sheet1!$H$1:$H$65536,[5]Sheet1!$J$1:$J$65536),0) -> 11782 | K11: =IFERROR(_xlfn.XLOOKUP(B11,[6]Sheet1!$H$1:$H$65536,[6]Sheet1!$J$1:$J$65536),0) -> 11822 | L11: =IFERROR(_xlfn.XLOOKUP(B11,[7]Sheet1!$H$1:$H$65536,[7]Sheet1!$J$1:$J$65536),0) -> 11961 | M11: =IFERROR(_xlfn.XLOOKUP(B11,[8]Sheet1!$H$1:$H$65536,[8]Sheet1!$J$1:$J$65536),0) -> 12218 | N11: =IFERROR(_xlfn.XLOOKUP(B11,[9]Sheet1!$H$1:$H$65536,[9]Sheet1!$J$1:$J$65536),0) -> 12542 | O11: =IFERROR(_xlfn.XLOOKUP(B11,[10]Sheet1!$H$1:$H$65536,[10]Sheet1!$J$1:$J$65536),0) -> 2849 | P11: =IFERROR(_xlfn.XLOOKUP(B11,[11]Sheet1!$H$1:$H$65536,[11]Sheet1!$J$1:$J$65536),0) -> 3613 | Q11: =IFERROR(_xlfn.XLOOKUP(B11,[12]Sheet1!$H$1:$H$65536,[12]Sheet1!$J$1:$J$65536),0) -> 0 | R11: =IFERROR(_xlfn.XLOOKUP(B11,[13]Sheet1!$H$1:$H$65536,[13]Sheet1!$J$1:$J$65536),) -> 0 | S11: =IFERROR(_xlfn.XLOOKUP(B11,[14]Sheet1!$H$1:$H$65536,[14]Sheet1!$K$1:$K$65536),0) -> 0 | T11: =IFERROR(_xlfn.XLOOKUP(B11,[15]Sheet1!$H$1:$H$65536,[15]Sheet1!$J$1:$J$65536),0) -> 0 | U11: =IFERROR(_xlfn.XLOOKUP(B11,[16]Sheet1!$H$1:$H$65536,[16]Sheet1!$J$1:$J$65536),0) -> 0 | V11: =IFERROR(_xlfn.XLOOKUP(B11,[17]Sheet1!$H$1:$H$65536,[17]Sheet1!$J$1:$J$65536),0) -> 0 | W11: =IFERROR(_xlfn.XLOOKUP(B11,[18]Sheet1!$H$1:$H$65536,[18]Sheet1!$J$1:$J$65536),0) -> 0 | X11: =IFERROR(_xlfn.XLOOKUP(B11,[19]Sheet1!$H$1:$H$65536,[19]Sheet1!$J$1:$J$65536),0) -> 0 | Y11: =IFERROR(_xlfn.XLOOKUP(B11,[20]Sheet1!$H$1:$H$65536,[20]Sheet1!$J$1:$J$65536),0) -> 0 | Z11: =IFERROR(_xlfn.XLOOKUP(B11,[21]Sheet1!$H$1:$H$65536,[21]Sheet1!$J$1:$J$65536),0) -> 0
A12: =MID(B12,3,2) -> T2 | B12: EET225075 | C12: =_xlfn.XLOOKUP(B12,IP구분!A:A,IP구분!C:C) -> 퍼글러 | D12: 베이피 퍼글러 키링-래비드 래빗 | E12: =IFERROR(_xlfn.XLOOKUP(B12,단가!A:A,단가!C:C),0) -> 3236 | F12: =IFERROR(_xlfn.XLOOKUP(B12,'[1]2609 재고'!$I$1:$I$65536,'[1]2609 재고'!$K$1:$K$65536),0) -> 5851 | G12: =IFERROR(_xlfn.XLOOKUP(B12,[2]Sheet1!$H$1:$H$65536,[2]Sheet1!$K$1:$K$65536),0) -> 6634 | H12: =IFERROR(_xlfn.XLOOKUP(B12,[3]Sheet1!$H$1:$H$65536,[3]Sheet1!$J$1:$J$65536),0) -> 7277 | I12: =IFERROR(_xlfn.XLOOKUP(B12,[4]Sheet1!$H$1:$H$65536,[4]Sheet1!$J$1:$J$65536),0) -> 7958 | J12: =IFERROR(_xlfn.XLOOKUP(B12,[5]Sheet1!$H$1:$H$65536,[5]Sheet1!$J$1:$J$65536),0) -> 8684 | K12: =IFERROR(_xlfn.XLOOKUP(B12,[6]Sheet1!$H$1:$H$65536,[6]Sheet1!$J$1:$J$65536),0) -> 9238 | L12: =IFERROR(_xlfn.XLOOKUP(B12,[7]Sheet1!$H$1:$H$65536,[7]Sheet1!$J$1:$J$65536),0) -> 10071 | M12: =IFERROR(_xlfn.XLOOKUP(B12,[8]Sheet1!$H$1:$H$65536,[8]Sheet1!$J$1:$J$65536),0) -> 11058 | N12: =IFERROR(_xlfn.XLOOKUP(B12,[9]Sheet1!$H$1:$H$65536,[9]Sheet1!$J$1:$J$65536),0) -> 11973 | O12: =IFERROR(_xlfn.XLOOKUP(B12,[10]Sheet1!$H$1:$H$65536,[10]Sheet1!$J$1:$J$65536),0) -> 0 | P12: =IFERROR(_xlfn.XLOOKUP(B12,[11]Sheet1!$H$1:$H$65536,[11]Sheet1!$J$1:$J$65536),0) -> 0 | Q12: =IFERROR(_xlfn.XLOOKUP(B12,[12]Sheet1!$H$1:$H$65536,[12]Sheet1!$J$1:$J$65536),0) -> 0 | R12: =IFERROR(_xlfn.XLOOKUP(B12,[13]Sheet1!$H$1:$H$65536,[13]Sheet1!$J$1:$J$65536),) -> 0 | S12: =IFERROR(_xlfn.XLOOKUP(B12,[14]Sheet1!$H$1:$H$65536,[14]Sheet1!$K$1:$K$65536),0) -> 0 | T12: =IFERROR(_xlfn.XLOOKUP(B12,[15]Sheet1!$H$1:$H$65536,[15]Sheet1!$J$1:$J$65536),0) -> 0 | U12: =IFERROR(_xlfn.XLOOKUP(B12,[16]Sheet1!$H$1:$H$65536,[16]Sheet1!$J$1:$J$65536),0) -> 0 | V12: =IFERROR(_xlfn.XLOOKUP(B12,[17]Sheet1!$H$1:$H$65536,[17]Sheet1!$J$1:$J$65536),0) -> 0 | W12: =IFERROR(_xlfn.XLOOKUP(B12,[18]Sheet1!$H$1:$H$65536,[18]Sheet1!$J$1:$J$65536),0) -> 0 | X12: =IFERROR(_xlfn.XLOOKUP(B12,[19]Sheet1!$H$1:$H$65536,[19]Sheet1!$J$1:$J$65536),0) -> 0 | Y12: =IFERROR(_xlfn.XLOOKUP(B12,[20]Sheet1!$H$1:$H$65536,[20]Sheet1!$J$1:$J$65536),0) -> 0 | Z12: =IFERROR(_xlfn.XLOOKUP(B12,[21]Sheet1!$H$1:$H$65536,[21]Sheet1!$J$1:$J$65536),0) -> 0
A13: =MID(B13,3,2) -> T2 | B13: EET226004 | C13: =_xlfn.XLOOKUP(B13,IP구분!A:A,IP구분!C:C) -> 퍼글러 | D13: 퍼글러 피규어 키체인 블라인드백-크리스마스 | E13: =IFERROR(_xlfn.XLOOKUP(B13,단가!A:A,단가!C:C),0) -> 1673 | F13: =IFERROR(_xlfn.XLOOKUP(B13,'[1]2609 재고'!$I$1:$I$65536,'[1]2609 재고'!$K$1:$K$65536),0) -> 22512 | G13: =IFERROR(_xlfn.XLOOKUP(B13,[2]Sheet1!$H$1:$H$65536,[2]Sheet1!$K$1:$K$65536),0) -> 23040 | H13: =IFERROR(_xlfn.XLOOKUP(B13,[3]Sheet1!$H$1:$H$65536,[3]Sheet1!$J$1:$J$65536),0) -> 0 | I13: =IFERROR(_xlfn.XLOOKUP(B13,[4]Sheet1!$H$1:$H$65536,[4]Sheet1!$J$1:$J$65536),0) -> 0 | J13: =IFERROR(_xlfn.XLOOKUP(B13,[5]Sheet1!$H$1:$H$65536,[5]Sheet1!$J$1:$J$65536),0) -> 0 | K13: =IFERROR(_xlfn.XLOOKUP(B13,[6]Sheet1!$H$1:$H$65536,[6]Sheet1!$J$1:$J$65536),0) -> 0 | L13: =IFERROR(_xlfn.XLOOKUP(B13,[7]Sheet1!$H$1:$H$65536,[7]Sheet1!$J$1:$J$65536),0) -> 0 | M13: =IFERROR(_xlfn.XLOOKUP(B13,[8]Sheet1!$H$1:$H$65536,[8]Sheet1!$J$1:$J$65536),0) -> 0 | N13: =IFERROR(_xlfn.XLOOKUP(B13,[9]Sheet1!$H$1:$H$65536,[9]Sheet1!$J$1:$J$65536),0) -> 0 | O13: =IFERROR(_xlfn.XLOOKUP(B13,[10]Sheet1!$H$1:$H$65536,[10]Sheet1!$J$1:$J$65536),0) -> 0 | P13: =IFERROR(_xlfn.XLOOKUP(B13,[11]Sheet1!$H$1:$H$65536,[11]Sheet1!$J$1:$J$65536),0) -> 0 | Q13: =IFERROR(_xlfn.XLOOKUP(B13,[12]Sheet1!$H$1:$H$65536,[12]Sheet1!$J$1:$J$65536),0) -> 0 | R13: =IFERROR(_xlfn.XLOOKUP(B13,[13]Sheet1!$H$1:$H$65536,[13]Sheet1!$J$1:$J$65536),) -> 0 | S13: =IFERROR(_xlfn.XLOOKUP(B13,[14]Sheet1!$H$1:$H$65536,[14]Sheet1!$K$1:$K$65536),0) -> 0 | T13: =IFERROR(_xlfn.XLOOKUP(B13,[15]Sheet1!$H$1:$H$65536,[15]Sheet1!$J$1:$J$65536),0) -> 0 | U13: =IFERROR(_xlfn.XLOOKUP(B13,[16]Sheet1!$H$1:$H$65536,[16]Sheet1!$J$1:$J$65536),0) -> 0 | V13: =IFERROR(_xlfn.XLOOKUP(B13,[17]Sheet1!$H$1:$H$65536,[17]Sheet1!$J$1:$J$65536),0) -> 0 | W13: =IFERROR(_xlfn.XLOOKUP(B13,[18]Sheet1!$H$1:$H$65536,[18]Sheet1!$J$1:$J$65536),0) -> 0 | X13: =IFERROR(_xlfn.XLOOKUP(B13,[19]Sheet1!$H$1:$H$65536,[19]Sheet1!$J$1:$J$65536),0) -> 0 | Y13: =IFERROR(_xlfn.XLOOKUP(B13,[20]Sheet1!$H$1:$H$65536,[20]Sheet1!$J$1:$J$65536),0) -> 0 | Z13: =IFERROR(_xlfn.XLOOKUP(B13,[21]Sheet1!$H$1:$H$65536,[21]Sheet1!$J$1:$J$65536),0) -> 0
... A3411: =MID(B3411,3,2) -> M2 | B3411: PRM225005 | C3411: =_xlfn.XLOOKUP(B3411,IP구분!A:A,IP구분!C:C) -> 뽀로로 | D3411: 뽀로로 화이트보드(미니) | E3411: =IFERROR(_xlfn.XLOOKUP(B3411,단가!A:A,단가!C:C),0) -> - | F3411: =IFERROR(_xlfn.XLOOKUP(B3411,'[1]2609 재고'!$I$1:$I$65536,'[1]2609 재고'!$K$1:$K$65536),0) -> 0 | G3411: =IFERROR(_xlfn.XLOOKUP(B3411,[2]Sheet1!$H$1:$H$65536,[2]Sheet1!$K$1:$K$65536),0) -> 0 | H3411: =IFERROR(_xlfn.XLOOKUP(B3411,[3]Sheet1!$H$1:$H$65536,[3]Sheet1!$J$1:$J$65536),0) -> 0 | I3411: =IFERROR(_xlfn.XLOOKUP(B3411,[4]Sheet1!$H$1:$H$65536,[4]Sheet1!$J$1:$J$65536),0) -> 1 | J3411: =IFERROR(_xlfn.XLOOKUP(B3411,[5]Sheet1!$H$1:$H$65536,[5]Sheet1!$J$1:$J$65536),0) -> 4 | K3411: =IFERROR(_xlfn.XLOOKUP(B3411,[6]Sheet1!$H$1:$H$65536,[6]Sheet1!$J$1:$J$65536),0) -> 13 | L3411: =IFERROR(_xlfn.XLOOKUP(B3411,[7]Sheet1!$H$1:$H$65536,[7]Sheet1!$J$1:$J$65536),0) -> 16 | M3411: =IFERROR(_xlfn.XLOOKUP(B3411,[8]Sheet1!$H$1:$H$65536,[8]Sheet1!$J$1:$J$65536),0) -> 14 | N3411: =IFERROR(_xlfn.XLOOKUP(B3411,[9]Sheet1!$H$1:$H$65536,[9]Sheet1!$J$1:$J$65536),0) -> 14 | O3411: =IFERROR(_xlfn.XLOOKUP(B3411,[10]Sheet1!$H$1:$H$65536,[10]Sheet1!$J$1:$J$65536),0) -> 24 | P3411: =IFERROR(_xlfn.XLOOKUP(B3411,[11]Sheet1!$H$1:$H$65536,[11]Sheet1!$J$1:$J$65536),0) -> 24 | Q3411: =IFERROR(_xlfn.XLOOKUP(B3411,[12]Sheet1!$H$1:$H$65536,[12]Sheet1!$J$1:$J$65536),0) -> 24 | R3411: =IFERROR(_xlfn.XLOOKUP(B3411,[13]Sheet1!$H$1:$H$65536,[13]Sheet1!$J$1:$J$65536),) -> 25 | S3411: =IFERROR(_xlfn.XLOOKUP(B3411,[14]Sheet1!$H$1:$H$65536,[14]Sheet1!$K$1:$K$65536),0) -> 26 | T3411: =IFERROR(_xlfn.XLOOKUP(B3411,[15]Sheet1!$H$1:$H$65536,[15]Sheet1!$J$1:$J$65536),0) -> 27 | U3411: =IFERROR(_xlfn.XLOOKUP(B3411,[16]Sheet1!$H$1:$H$65536,[16]Sheet1!$J$1:$J$65536),0) -> 31 | V3411: =IFERROR(_xlfn.XLOOKUP(B3411,[17]Sheet1!$H$1:$H$65536,[17]Sheet1!$J$1:$J$65536),0) -> 33 | W3411: =IFERROR(_xlfn.XLOOKUP(B3411,[18]Sheet1!$H$1:$H$65536,[18]Sheet1!$J$1:$J$65536),0) -> 38 | X3411: =IFERROR(_xlfn.XLOOKUP(B3411,[19]Sheet1!$H$1:$H$65536,[19]Sheet1!$J$1:$J$65536),0) -> 39 | Y3411: =IFERROR(_xlfn.XLOOKUP(B3411,[20]Sheet1!$H$1:$H$65536,[20]Sheet1!$J$1:$J$65536),0) -> 40 | Z3411: =IFERROR(_xlfn.XLOOKUP(B3411,[21]Sheet1!$H$1:$H$65536,[21]Sheet1!$J$1:$J$65536),0) -> 0

Sheet 단가
A1: 품목 | B1: 품목명 | C1: 단가
A2: DCP123001 | B2: 데코데코 말캉말캉 종이 스퀴시 문구점 (구간) | C2: 3275
A3: DCP123002 | B3: 데코데코 말캉말캉 슬라임 스퀴시 (구간) | C3: 5811
A4: DCP123003 | B4: 데코데코 말캉말캉 토핑 스퀴시 (구간) | C4: 5401
A5: DCP123004 | B5: 데코데코 말캉말캉 종이 스퀴시 편의점 | C5: 3177
A6: DCP124001 | B6: 데코데코 매직글리터 - 솜인형 키링 만들기 | C6: 5388
A7: DCP124002 | B7: 데코데코 아이돌 메이크업 색칠북 | C7: 5795
A8: DCP124003 | B8: 데코데코 요요유니 슬라임 스퀴시 (플레이타임 전용) | C8: -
A9: DCP124004 | B9: 데코데코 미니 스퀴시 사장의 포용계 키트 | C9: 6365
A10: DCP125001 | B10: 데코데코 포장의 달인 | C10: 2465
A11: DCP125002 | B11: 데코데코 말캉말캉 디저트 스퀴시북 | C11: 3408
A12: DCT122001 | B12: 데코데코 말캉이 메이킷 | C12: 15008
A13: DCT122002 | B13: 데코데코 말캉이 메이킷 - 디저트 키트 | C13: 7046
A14: DCT122003 | B14: 데코데코 말캉이 메이킷 - 아이스크림 키트 | C14: 5614
A15: DCT122004 | B15: 데코데코 시크릿 캐비닛 러블리 핑크 | C15: 12997
A16: DCT122005 | B16: 데코데코 시크릿 캐비닛 트렌디 퍼플 | C16: 12745
A17: DCT122006 | B17: 데코데코 유니콘 라떼 글리터 슬라임 만들기 | C17: 5074
A18: DCT122008 | B18: 데코데코 달콤 디저트 슈링클스 키링 만들기 | C18: 4520
A19: DCT122009 | B19: 데코데코 냠냠파티 디폼블럭 만들기 | C19: 2562
A20: DCT123001 | B20: 데코데코 롤링 스티커펜 디럭스 다꾸 키트 | C20: 11716
... A36: DCT124009 | B36: 데코데코팬시 데스크 청소기 | C36: 2768
A37: DCT124010 | B37: 데코데코팬시 포토앨범 | C37: -
A38: DCT124011 | B38: 데코데코팬시 투명 파우치 | C38: 2194
A39: DCT124012 | B39: 데코데코팬시 인형키링_체리 | C39: 2035
A40: DCT124013 | B40: 데코데코팬시 인형키링_포도 | C40: 2035
A41: DCT124014 | B41: 요요유니 라떼 글리터 슬라임 만들기 | C41: -
A42: DCT124015 | B42: 데코데코팬시 인형키링_레몬 | C42: 2035
A43: DCT124016 | B43: 데코데코팬시 인형키링_소다 | C43: 2441
A44: DCT124017 | B44: 데코데코팬시 펜 파우치 | C44: -
A45: DCT124018 | B45: 데코데코팬시 스마트그립 | C45: 986
A46: DCT124019 | B46: 데코데코팬시 짝꿍 자석키링 | C46: -
A47: DCT124020 | B47: 데코데코팬시 아크릴집게 세트 | C47: -
A48: DCT124021 | B48: 데코데코팬시 젤리 스티커1_체리&레몬 | C48: 290
A49: DCT124022 | B49: 데코데코팬시 젤리 스티커1_포도&소다 | C49: 290
A50: DCT124023 | B50: 데코데코팬시 젤리 스티커1_말캉프렌즈 | C50: 290
A51: DCT124024 | B51: 데코데코팬시 노트_짝꿍1 | C51: 390
A52: DCT124025 | B52: 데코데코팬시 노트_짝꿍2 | C52: 390
A53: DCT124026 | B53: 데코데코팬시 노트_깜짝1 | C53: 390
A54: DCT124027 | B54: 데코데코팬시 노트_깜짝2 | C54: -
A55: DCT124028 | B55: 데코데코팬시 L홀더 1 | C55: -
...

Sheet IP구분
A1: 품목 | B1: 품목명 | C1: 품목군명
A2: AFFS00004 | B2: 정백당(클레임용) | C2: 원부자재
A3: AIIP00100 | B3: 뽀로로 식습관_뽀로로 IC | C3: 원부자재
A4: EEF200002 | B4: 뽀로로 음료 푸쉬풀캡 | C4: 원부자재
A5: AFFS00002 | B5: 탈지분유 | C5: 원부자재
A6: AIIP00116 | B6: 레스큐 타요 집게트럭 너클 _IC&PCB | C6: 원부자재
A7: AIIP00118 | B7: 데코데코 빵쿵즈 Mix-up Main IC | C7: 원부자재
A8: BAFP00003 | B8: 뽀로로 음료 24입 외박스 | C8: 원부자재
A9: AFFS00001 | B9: 정백당 | C9: 원부자재
A10: AFFS00005 | B10: 탈지분유(클레임용) | C10: 원부자재
A11: AIIP00074 | B11: 타요 붕붕카 IC | C11: 타요
A12: AIIP00086 | B12: 베이비 타요 주차장_타요 IC | C12: 타요
... A316: HCL125001 | B316: (해치X최고심) 봉제 키링 | C316: 해치
A317: DTOY00222 | B317: 4style mini cars_Speed
A318: DTOY00324 | B318: TAYO HIGHWAY RACING PLAY_wheel cars
A319: AIIP00108 | B319: 뽀로로 디제이 팡팡 모터 IC
A320: DTOY00219 | B320: 4style mini cars_Poco
A321: DTOY00256 | B321: 4style mini cars_Nuri
A322: DTOY00259 | B322: Mini Tayo bus Set_Tayo
A323: DTOY00262 | B323: Mini Tayo bus Set_Logi
A324: DTOY00273 | B324: 4 style mini cars_Reo
A325: DTOY00378 | B325: Mini Tayo bus set_Heavy equipment Tayo
A326: EET224083 | B326: 해치멀 얼라이브_드래글 | C326: 해치멀
A327: AIIP00103 | B327: 띠띠뽀 차량기지 센터 IC
A328: AIIP00106 | B328: 띠띠뽀 국제 메인역 IC
A329: PRE126011 | B329: T1 X 잔망루피_핀뱃지 6종세트 | C329: 잔망루피
A330: PRE126014 | B330: T1 X 잔망루피_봉제 12cm 키링_Faker | C330: 잔망루피
A331: PRE126015 | B331: T1 X 잔망루피_봉제 12cm 키링_Peyz | C331: 잔망루피
A332: PRE126009 | B332: T1 X 잔망루피_데스크 매트_Black | C332: 잔망루피
A333: PRE126010 | B333: T1 X 잔망루피_데코스티커팩 | C333: 잔망루피
A334: PRE126027 | B334: T1 X 잔망루피_리버시블 목베개쿠션_Doran | C334: 잔망루피
A335: PRF126028 | B335: 잔망비타 자두 (F2, RRP) | C335: 잔망루피
A336: PRF126043 | B336: 잔망스윗 아몬드초코 단백ㅋㅋ | C336: 잔망루피
A337: PRL121021 | B337: 잔망루피 클리어 리무버 스티커_블루 | C337: 잔망루피
A338: PRL121030 | B338: 잔망루피 데코 리무버 스티커_코스튬 | C338: 잔망루피
A339: PRL121033 | B339: 잔망루피 아크릴 볼펜_퍼플 | C339: 잔망루피
A340: PRE126008 | B340: T1 X 잔망루피_데스크 매트_Pink | C340: 잔망루피
... A432: PRF126017 | B432: 빅뽀로로 PET 사과 (용지아국제) | C432: 뽀로로
A433: DTOY00218 | B433: 4style mini cars_Bongbong
A434: DTOY00323 | B434: Mini Tayo bus Set_11th, heavy equipment Bulk set
...
